Workbook

Sheet Encounter Sheet
B2: GM Encounter Sheet | H2: Round # | L2: Scene Notes
H3: 1
B5: Active Combatant List | L5: Light Screen x2
B6: Enemy 1 | C6: Combatant Name | D6: Combatant Category | E6: Current HP | F6: Link to full Character Sheet
C7: Mismagius | D7: Boss (Alpha) | E7: 19
C8: Current Buffs & Notes | F8: # of HP Bars Remaining | G8: TRUE | H8: FALSE | I8: FALSE | J8: FALSE
C9: Current Debuffs | D9: Dazed | F9: Turns left this Round | G9: FALSE | H9: FALSE | I9: FALSE
B11: Enemy 2 | C11: Combatant Name | D11: Combatant Category | E11: Current HP | F11: Link to full Character Sheet
C12: Golett 1 | E12: 1
C13: Current Buffs & Notes | F13: # of HP Bars Remaining | G13: TRUE | H13: FALSE | I13: FALSE | J13: FALSE
C14: Current Debuffs | F14: Turns left this Round | G14: FALSE | H14: FALSE | I14: FALSE
B16: Enemy 3 | C16: Combatant Name | D16: Combatant Category | E16: Current HP | F16: Link to full Character Sheet
C17: Gollet 2 | E17: 1
C18: Current Buffs & Notes | D18: Offensive | F18: # of HP Bars Remaining | G18: TRUE | H18: FALSE | I18: FALSE | J18: FALSE | L18: Mini Damage Calculator
C19: Current Debuffs | F19: Turns left this Round | G19: FALSE | H19: FALSE | I19: FALSE
B21: Enemy 4 | C21: Combatant Name | D21: Combatant Category | E21: Current HP | F21: Link to full Character Sheet | L21: Starting HP | M21: Damage Dealt | N21: Resolving HP
C22: Gollet 3 | E22: 1 | N22: =IFERROR(IF(L26="HP Loss",MINUS(L22,M22),MINUS(L22,MULTIPLY(L26,MINUS(M22,SUM(M26,N26))))),"--") -> 0
C23: Current Buffs & Notes | F23: # of HP Bars Remaining | G23: TRUE | H23: FALSE | I23: FALSE | J23: FALSE
C24: Current Debuffs | D24: Dazed | F24: Turns left this Round | G24: TRUE | H24: FALSE | I24: FALSE | L24: Attack's Effectiveness | M24: Relevant Defense Stat | N24: Damage Reduction
B26: Enemy 5 | C26: Combatant Name | D26: Combatant Category | E26: Current HP | F26: Link to full Character Sheet | L26: 1
C27: Shuppet 1 | E27: 3
C28: Current Buffs & Notes | F28: # of HP Bars Remaining | G28: TRUE | H28: FALSE | I28: FALSE | J28: FALSE | L28: Type Effectivness Calculator
C29: Current Debuffs | F29: Turns left this Round | G29: FALSE | H29: FALSE | I29: FALSE
B31: Enemy 6 | C31: Combatant Name | D31: Combatant Category | E31: Current HP | F31: Link to full Character Sheet | L31: Attack Type | M31: Defender Type 1 | N31: Defender Type 2
C32: Shuppet 2 | E32: 1
C33: Current Buffs & Notes | F33: # of HP Bars Remaining | G33: FALSE | H33: FALSE | I33: FALSE | J33: FALSE | L33: =IFERROR( IFS( IF( NOT(ISBLANK(N32)), MULTIPLY( HLOOKUP(L32,Calculations!$F$1:$X$20,MATCH(M32,Calculations!$F$1:$F$20),FALSE), HLOOKUP(L32,Calculations!$F$1:$X$20,MATCH(N32,Calculations!$F$1:$F$20),FALSE)), HLOOKUP(L32,Calculations!$F$1:$X$20,MATCH(M32,Calculations!$F$1:$F$20),FALSE))=0.25, "Double Resist! [.25x]", IF( NOT(ISBLANK(N32)), MULTIPLY( HLOOKUP(L32,Calculations!$F$1:$X$20,MATCH(M32,Calculations!$F$1:$F$20),FALSE), HLOOKUP(L32,Calculations!$F$1:$X$20,MATCH(N32,Calculations!$F$1:$F$20),FALSE)), HLOOKUP(L32,Calculations!$F$1:$X$20,MATCH(M32,Calculations!$F$1:$F$20),FALSE))=0.5, "Resist! [.5x]", IF( NOT(ISBLANK(N32)), MULTIPLY( HLOOKUP(L32,Calculations!$F$1:$X$20,MATCH(M32,Calculations!$F$1:$F$20),FALSE), HLOOKUP(L32,Calculations!$F$1:$X$20,MATCH(N32,Calculations!$F$1:$F$20),FALSE)), HLOOKUP(L32,Calculations!$F$1:$X$20,MATCH(M32,Calculations!$F$1:$F$20),FALSE))=1, "Neutral Damage [1x]", IF( NOT(ISBLANK(N32)), MULTIPLY( HLOOKUP(L32,Calculations!$F$1:$X$20,MATCH(M32,Calculations!$F$1:$F$20),FALSE), HLOOKUP(L32,Calculations!$F$1:$X$20,MATCH(N32,Calculations!$F$1:$F$20),FALSE)), HLOOKUP(L32,Calculations!$F$1:$X$20,MATCH(M32,Calculations!$F$1:$F$20),FALSE))=2, "Super Effective! [1.5x]", IF( NOT(ISBLANK(N32)), MULTIPLY( HLOOKUP(L32,Calculations!$F$1:$X$20,MATCH(M32,Calculations!$F$1:$F$20),FALSE), HLOOKUP(L32,Calculations!$F$1:$X$20,MATCH(N32,Calculations!$F$1:$F$20),FALSE)), HLOOKUP(L32,Calculations!$F$1:$X$20,MATCH(M32,Calculations!$F$1:$F$20),FALSE))=4, "Double Effectiveness! [2x]", IF( NOT(ISBLANK(N32)), MULTIPLY( HLOOKUP(L32,Calculations!$F$1:$X$20,MATCH(M32,Calculations!$F$1:$F$20),FALSE), HLOOKUP(L32,Calculations!$F$1:$X$20,MATCH(N32,Calculations!$F$1:$F$20),FALSE)), HLOOKUP(L32,Calculations!$F$1:$X$20,MATCH(M32,Calculations!$F$1:$F$20),FALSE))=0, "Immune! [0x]"), "Slot some types to get some info!") -> Slot some types to get some info!
C34: Current Debuffs | F34: Turns left this Round | G34: FALSE | H34: FALSE | I34: FALSE
B36: Enemy 7 | C36: Combatant Name | D36: Combatant Category | E36: Current HP | F36: Link to full Character Sheet
C37: Shuppet 3 | E37: 3
C38: Current Buffs & Notes | D38: Drowsy | F38: # of HP Bars Remaining | G38: FALSE | H38: FALSE | I38: FALSE | J38: FALSE
C39: Current Debuffs | F39: Turns left this Round | G39: FALSE | H39: FALSE | I39: FALSE
B41: Enemy 8 | C41: Combatant Name | D41: Combatant Category | E41: Current HP | F41: Link to full Character Sheet
C42: Portal 1/2/3 | E42: 100
C43: Current Buffs & Notes | F43: # of HP Bars Remaining | G43: TRUE | H43: FALSE | I43: FALSE | J43: FALSE
C44: Current Debuffs | F44: Turns left this Round | G44: TRUE | H44: FALSE | I44: FALSE
B46: Enemy 9 | C46: Combatant Name | D46: Combatant Category | E46: Current HP | F46: Link to full Character Sheet
C48: Current Buffs & Notes | F48: # of HP Bars Remaining | G48: TRUE | H48: FALSE | I48: FALSE | J48: FALSE
C49: Current Debuffs | F49: Turns left this Round | G49: TRUE | H49: FALSE | I49: FALSE
B51: Enemy 10 | C51: Combatant Name | D51: Combatant Category | E51: Current HP | F51: Link to full Character Sheet
C53: Current Buffs & Notes | F53: # of HP Bars Remaining | G53: TRUE | H53: FALSE | I53: FALSE | J53: FALSE
...

Sheet  Encounter Balance Calculator
A1: Encounter Balance
A3: Allies | D3: Enemies
A4: Trainer points | B4: Trainer lvl | C4: Advantages | D4: Trainer points | E4: Pkmn points | F4: Advantages
A5: 3 | B5: 1
A6: Pkmn points | B6: Pkmn max lvl | C6: Disavantages | D6: Trainer lvl | E6: Pkmn lvl | F6: Disavantages
A7: 3 | B7: 5
A8: Balance: | B8: =IFS( F9-C9<=-4, "Very Easy", F9-C9<=-1, "Easy", F9-C9<=1, "Balanced", F9-C9<=4, "Hard", F9-C9>=5, "Very Hard" ) -> Very Easy | C8: Ally Total | D8: Trainer value | E8: Pkmn Value | F8: Enemy Total
C9: =A5+A7+C5-C7 -> 6 | D9: =IFS(D7<=B5-4, 0.5, D7>=B5+4, 2, TRUE, 1) -> 1 | E9: =IFS(E7<=B7/2, 0.5, E7>=B7*2, 3, TRUE, 1) -> 0.5 | F9: =D5+E5+F5-F7 -> 0

Sheet References
B2: Combatant Category Reference
B3: Name | C3: Combatant Rules
C4: =IFERROR(VLOOKUP($B$4,'Combatant Category Data'!A$2:B8,2,FALSE),"--") -> --
B5: Boss Perks | C5: =IF(B4="","--",IF(OR(B4="Boss (Alpha)",B4="Boss (Guardian)"),'Combatant Category Data'!C3,"N/A")) -> --
B7: Boss Perk Reference
B8: Name | C8: Boss Perk Rules
C9: =IFERROR(VLOOKUP($B$9,'Combatant Category Data'!A$2:$B54,2,FALSE),"--") -> --
B11: Surge Token Reference
B12: Name | C12: Surge Token Rules
C13: =IFERROR(VLOOKUP($B$13,'Combatant Category Data'!A$2:$B54,2,FALSE),"--") -> --
B15: Stance Reference
B16: Name | C16: Stance Effect | G16: Break Condition
C17: =IFERROR(VLOOKUP($B$17,'Combatant Category Data'!A$2:$B54,2,FALSE),"--") -> -- | G17: =IFERROR(VLOOKUP($B$17,'Combatant Category Data'!A$2:$C54,3,FALSE),"--") -> --
B19: Lair Action Reference
B20: Name | C20: Lair Action Rules | G20: Example
C21: =IFERROR(VLOOKUP($B$21,'Combatant Category Data'!A$2:$B54,2,FALSE),"--") -> -- | G21: =IFERROR(VLOOKUP($B$21,'Combatant Category Data'!A$2:$C54,3,FALSE),"--") -> --
B23: Attack Reference
B24: Name | C24: Type | D24: Category | E24: Frequency | F24: Range | G24: AC | DB | H24: Effect
C25: =IFERROR(VLOOKUP(B25,'Attack Data'!$A$2:$J54,2,FALSE),"--") -> -- | D25: =IFERROR(VLOOKUP(B25,'Attack Data'!$A$2:$J54,3,FALSE),"--") -> -- | E25: =IFERROR(VLOOKUP(B25,'Attack Data'!$A$2:$J54,4,FALSE),"--") -> -- | F25: =IFERROR(VLOOKUP(B25,'Attack Data'!$A$2:$J54,5,FALSE),"--") -> -- | G25: =IFERROR(CONCATENATE(VLOOKUP(B25,'Attack Data'!$A$2:$J54,6,FALSE)," | ",VLOOKUP(B25,'Attack Data'!$A$2:$J54,7,FALSE)),"--") -> -- | H25: =IFERROR(CONCATENATE(VLOOKUP(B25,'Attack Data'!$A$2:$J54,8,FALSE),CHAR(10),CHAR(10),"Rank 2 Effect:",CHAR(10),VLOOKUP(B25,'Attack Data'!$A$2:$J54,9,FALSE)),"--") -> --
B27: Role Reference
B28: Name | C28: Rank 1 Effect | G28: Rank 2 Effect
C29: =IFERROR(VLOOKUP($B$29,'Role Data'!$A$2:$C54,2,FALSE),"--") -> -- | G29: =IFERROR(VLOOKUP($B$29,'Role Data'!$A$2:$C54,3,FALSE),"--") -> --
B31: Status & Condition Reference
B32: Name | C32: Effects
B33: Suppressed | C33: =IFERROR(VLOOKUP($B$33,'Misc Data'!$C$2:$D54,2,FALSE),"--") -> » Whenever a Suppressed Combatant uses an EOT Attack, after Damage Calculations, they become Vulnerable until the end of the next Round. » Whenever a Suppressed Combatant uses a Scene or Daily Attack or Ability, after its resolution, they become Vulnerable and Weakened until the end of the next Round. » Combatants with a Boss Template are automatically cured of the Suppressed Affliction when they end their last Turn in a Round.
B35: Capability Reference
B36: Name | C36: Effects
C37: =IFERROR(VLOOKUP($B$37,'Misc Data'!$A$2:$B54,2,FALSE),"--") -> --
B39: Maneuver Reference
B40: Name | C40: Range | D40: Action | E40: Target | F40: AC | G40: Effect
C41: =IFERROR(VLOOKUP($B$41,'OrderTechnique Data'!$K$2:$P54,2,FALSE),"--") -> -- | D41: =IFERROR(VLOOKUP($B$41,'OrderTechnique Data'!$K$2:$P54,3,FALSE),"--") -> -- | E41: =IFERROR(VLOOKUP($B$41,'OrderTechnique Data'!$K$2:$P54,4,FALSE),"--") -> -- | F41: =IFERROR(VLOOKUP($B$41,'OrderTechnique Data'!$K$2:$P54,5,FALSE),"--") -> -- | G41: =IFERROR(VLOOKUP($B$41,'OrderTechnique Data'!$K$2:$P54,6,FALSE),"--") -> --
B43: Keyword Reference
B44: Name | C44: Effects
C45: =IFERROR(VLOOKUP($B$45,'Misc Data'!$E$2:$F54,2,FALSE),"--") -> --
B47: Terrain Type & Environment Reference
B48: Name | C48: Effects
C49: =IFERROR(VLOOKUP($B$49,'Misc Data'!$G$2:$H54,2,FALSE),"--") -> --
B51: Item Reference
B52: Name | C52: Effects
C53: =IFERROR(VLOOKUP($B$53,'Item Data'!$M$2:$N54,2,FALSE),"--") -> --

Sheet Combatant Category Data
B1: Rules | C1: Perks
A3: Boss (Alpha) | B3: 1. Alpha Pokemon are always 5 Levels higher than your Player’s Maximum Pokemon Level. If their Maximum level is 40 or higher, this is instead 10 Levels. If these Pokemon are captured, they are reverted to the Player’s Maximum Pokemon Level. 2. Alpha Pokemon will have multiple Health Bars. If there are 1-2 Players in the Party, they have 2. If there are 3+ Players, they have 3. Whenever they would faint, they instead revert to their Maximum Hit Point value with the damage not carrying over, then they lose one of their Health Bars. This is considered a “Bar Break”. 3. Alpha Pokemon may have multiple Turns, equal to the number of Players in the opposing Party. 4. Alpha Pokemon have 8 Attack Slots by default instead of 6. 5. Effects that reference, Start of Turn, Per Turn, or End of Turn, only occur once per Round on their first applicable turn where they could occur, regardless of the number of turns they have. Additionally, Save Checks can only occur on the Boss’s last Turn in a Round unless provoked by an outside source such as the Help Maneuver. 6. Boss Pokemon also may perform Boss Perks, listed below, once at the start of a Scene and twice each time a Bar Break would occur and they don’t faint as a result. | C3: 1. Choose two different Combat Values below to gain +1 (Modifier or CS) in or reset to their Default Value: Any Stat except HP, Accuracy, Critical Hit Range, Effect Range, Save Checks. 2. The Boss is cured (or removes) of two of the following options: A Status Affliction, A Coat, A Condition other than Fainted. 3. The Boss gains a Surge Token or two if there are 3+ Players in the opposing Party. 4. The Boss may enter a Stance. This can only occur once per Scene. 5. The Boss may use a Lair Action. 6. The Boss may transform into a different form that you have prepared. Cannot be used at the start of Combat.
A4: Boss (Guardian) | B4: 1. Guardian Pokemon are instead always +10 Levels higher than your Player’s Maximum Pokemon Level. If they are Tier 3, this is instead 20 Levels. 2. Guardian Pokemon will have multiple Health Bars. If there are 1-2 Players in the Party, they have 2. If there are 3+ Players, they have 3. Whenever they would faint, they instead revert to their Maximum Hit Point value with the damage not carrying over, then they lose one of their Health Bars. This is considered a “Bar Break”. 3. Guardian Pokemon may have multiple Turns, equal to the number of Players in the opposing Party. 4. Guardian Pokemon instead have 10 Attack Slots and may choose any Attack from their Tutor Lists to gain, ignoring Pokemon Advancement. 5. Effects that reference, Start of Turn, Per Turn, or End of Turn, only occur once per Round on their first applicable turn where they could occur, regardless of the number of turns they have. Additionally, Save Checks can only occur on the Boss’s last Turn in a Round unless provoked by an outside source such as the Help Maneuver. 6. Boss Pokemon also may perform Boss Perks, listed below, once at the start of a Scene and twice each time a Bar Break would occur and they don’t faint as a result. At the end of each Round, the Guardian may use a Boss Perk. We recommend this be used mostly for Lair Actions. 7. At Level 30 Advancement, Guardians gain both an Ability and the 2nd Rank of their Role, instead of choosing between the two. | C4: 1. Choose two different Combat Values below to gain +1 (Modifier or CS) in or reset to their Default Value: Any Stat except HP, Accuracy, Critical Hit Range, Effect Range, Save Checks. 2. The Boss is cured (or removes) of two of the following options: A Status Affliction, A Coat, A Condition other than Fainted. 3. The Boss gains a Surge Token or two if there are 3+ Players in the opposing Party. 4. The Boss may enter a Stance. This can only occur once per Scene. 5. The Boss may use a Lair Action. 6. The Boss may transform into a different form that you have prepared. Cannot be used at the start of Combat.
A5: Boss (Swarm) | B5: 1. Instead of Statting multiple Pokemon, a Swarm Pokemon has one Character Sheet representing the entire Swarm. 2. The Swarm will have a number of Turns equal to the number of Players in the Opposing Party +1. 3. Whenever the Swarm Pokemon hits 0 HP, they instead permanently lose a Turn, then reset to 100% Hit Points. When they have no Turns remaining, the Swarm faints. 4. Swarm Pokemon do not have Battle Attack Lists, and instead may use any Attack they can learn. 5. Swarm Pokemon do not have Pokemon Roles, instead, each time they would gain an Ability from Pokemon Progression, they instead gain two. 6. There will be a number of tokens to represent on the Swarm equal to the number of Turns they currently have. These are all treated as different combatants. If multiple tokens would be targeted by the same Attack, it doesn't deal damage or apply the effect twice, but instead is treated as one step more effective. | C5: --
A6: Minion (Offensive) | B6: 1. Minions start with 3 Hit Points. Minions cannot lose hit points outside of listed methods here. They cannot restore Hit Points and cannot gain Temporary Hit Points. When Minions lose a Tick of Hit Points, they lose -1 Hit Point. Whenever they’re hit with a Damaging Attack, they lose -1 Hit Point but they lose an additional Hit Point per condition they meet: the Attack was Super Effective, 1-Target, or a Critical Hit. 2. Minions can use any Attack from their Level-Up or Tutor List, provided their level is high enough. If you stat a Minion before an Encounter, you may choose to instead have Minions only have a maximum of 3 Attacks. 3. The Level of all Minions are 5 less than the Maximum Pokemon Level of the Party. 4. Minions cannot perform Save Checks to cure the effects of Afflictions. 5. The Minion can use Damaging Attacks with the At-Will or EOT Frequency. Their Offensive Stat for Damage Calculations is equal to their Level. 6. The Minion can use Tactic Maneuvers. Swift Action Maneuvers are instead Standard Actions. | C6: --
A7: Minion (Defensive) | B7: 1. Minions start with 3 Hit Points. Minions cannot lose hit points outside of listed methods here. They cannot restore Hit Points and cannot gain Temporary Hit Points. When Minions lose a Tick of Hit Points, they lose -1 Hit Point. Whenever they’re hit with a Damaging Attack, they lose -1 Hit Point but they lose an additional Hit Point per condition they meet: the Attack was Super Effective, 1-Target, or a Critical Hit. 2. Minions can use any Attack from their Level-Up or Tutor List, provided their level is high enough. If you stat a Minion before an Encounter, you may choose to instead have Minions only have a maximum of 3 Attacks. 3. The Level of all Minions are 5 less than the Maximum Pokemon Level of the Party. 4. Minions cannot perform Save Checks to cure the effects of Afflictions. 5. The Minion can use Status Attacks with the At-Will Frequency without the Shield Keyword. 6. The Minions can use the Defend, Provoke and Intercept Maneuver. | C7: --
A8: Minion (Supportive) | B8: 1. Minions start with 3 Hit Points. Minions cannot lose hit points outside of listed methods here. They cannot restore Hit Points and cannot gain Temporary Hit Points. When Minions lose a Tick of Hit Points, they lose -1 Hit Point. Whenever they’re hit with a Damaging Attack, they lose -1 Hit Point but they lose an additional Hit Point per condition they meet: the Attack was Super Effective, 1-Target, or a Critical Hit. 2. Minions can use any Attack from their Level-Up or Tutor List, provided their level is high enough. If you stat a Minion before an Encounter, you may choose to instead have Minions only have a maximum of 3 Attacks. 3. The Level of all Minions are 5 less than the Maximum Pokemon Level of the Party. 4. Minions cannot perform Save Checks to cure the effects of Afflictions. 5. The Minion can use Status Attacks without the Shield Keyword or Scene x1 Frequency. 6. The Minion can use the Help Maneuver and Manipulate Maneuvers. | C8: --
A9: Pokemon | B9: -- | C9: --
A10: Trainer | B10: -- | C10: --
A11: NPC | B11: -- | C11: --
A13: Surge Token | B13: In order to even the scales of an Encounter, you could grant your Boss Surge Tokens either as a Boss Perk when they lose HP Bars or through special occasions such as an Environmental Conduit granting Surge Tokens while they’re active. Bosses can expend a Surge Token to perform any of the following as a Free Action either on their Turn, at the end of any Turn, or when it would be triggered (Such as using it for an Intercept Maneuver)
A14: Stance | B14: Sometimes Bosses enter a certain Stance that empowers them in a specific way, but also has the chance to leave them vulnerable if a weakness is exploited, leaving it as a high risk for higher output option. Each Stance has an Effect and a Break Condition. During their current Health Bar, they will have the Effect of the Stance applied to them. When they lose an HP Bar, they automatically lose their Stance’s Effects, however if the Break Condition occurs, they lose their Stance’s Effects and they become Vulnerable until the end of the next Round.
A15: Lair Action | B15: Lair Actions can be done easily by Guardians but sometimes by regular bosses in order to show that the environment is alive and often dangerous. Whenever you wish to perform a Lair Action, choose something from the Lair Action references below to enable on the Scene. These are just examples however and you can create your own effects if desired based on the environment your Players are in and what they’re facing.
A17: Damaging Attack | B17: Expend a Surge Token to perform a Damaging Attack. This Attack is resisted by an additional damage step, but this can be ignored if the Attack only has one Target or if another Surger Token is expended
A18: Status Attack | B18: Expend a Surge Token to perform a Status Attack. This Attack cannot have a range of “Self or Shield”. The Frequency of an Attack used this way is not expended.
A19: Maneuver | B19: Expend a Surge Token to perform a Maneuver. This Maneuver cannot be an Attack of Opportunity, Riposte or Respite. If they use the Help Maneuver, it ignores its restrictions.
A20: Resist Attack | B20: Expend a Surge Token to resist an Attack by an additional damage step. However, the boss's next Swift Action is expended.
A21: Save Check | B21: Expend a Surge Token to perfrom a Save Check. However, the boss's next Swift Action is Expended.
A23: Frenzied | B23: The Boss immediately becomes Enraged and cannot be cured of it while affected by this Stance. The user’s Damaging Attacks all gain the Smite Keyword and their Critical Hit Range is increased by +2. | C23: The Stance is broken when the Boss misses two Attacks or causes one of their enemies to faint.
A24: Shielded | B24: The Boss gains 5 Ticks of Temporary Hit Points and then becomes one step more resistant to all Physical or Special Category Attacks, depending on which of their Defense Stats are higher (choose on tie). | C24: The Stance is broken when the Boss loses all Temporary Hit Points gained this way or has their higher Defense Stat lowered to a negative CS Value
A25: Unyielding | B25: When the Boss enters an Unyielding Stance, they choose a Player to become their Rival (All their Pokemon are also treated as Rivals). Whenever the Boss Attacks a Rival, they have a +3 to Accuracy, ignore Damage Reduction and can’t have their Attacks resisted by the Rival by any means. | C25: The Stance is broken if a Rival of the Boss inflicts a Critical Hit against the Boss or avoids two Attacks.
A26: Charging | B26: While in this Stance, as a Swift Action, they gain +1 Charge Token. Whenever they’re hit by a Critical Hit or gain an Affliction, they lose a Charge Token. At the end of the Round, if they have at least one Charge Token, they expend all Charge Tokens and may use a Damaging Attack as a Free Action. For each Charge Token expended, they gain a benefit listed below: » The Attack gains +3 DB » The Attack gains the Smite Keyword or Sureshot if it already has Smite. » The Attack increases its Area of Effect by +1 | C26: The Stance automatically breaks after the resolution of the Attack used with the expended Charge Tokens or the end of the Round if they’re unable to use the Attack. The Stance is also considered to be broken if they lose their HP Bar before they would resolve this Attack.
A27: Desperate | B27: When the Boss enters the Desperate Stance, a Minion enters the Field for each opposing Player. Whenever the Boss would start their Turn, instead, two Minions may act or they may add another Minion to the Encounter. | C27: The Stance breaks when a number of Minions equal to double the number of Players in the opposing Party faint. After this Stance breaks, all Minions flee the Encounter.
A28: Regenerative | B28: The user has a +3 bonus to Save Checks and at the end of their Turns (Ignoring the end of Turn rule), they restore two Ticks of Hit Points or gain a Tick of Temporary Hit Points. | C28: The Stance breaks when the Boss is hit by a Critical Hit, recovers at least 8 Ticks of Hit Points, or recovers from at least 2 Status Afflictions while in the Stance.
A30: Area Retaliation | B30: Choose one Attack on the Boss’s Battle Attack List or an Attack that would make sense to come from the environment. Then choose either three 3x3 Zones or a 5x5 Zone, or whatever other Zone would make sense for the trigger (These Zones are visible to all Combatants). At the end of the next Round or upon a Trigger being fulfilled, the chosen Attack is used as a Free Action, Targeting all Combatants or Enemies of the Boss within the chosen Zones. If it was chosen from the Boss’s list of Attacks, it ignores Frequency and uses their Offensive Stat. Otherwise it follows the Environmental Damage rules under “Other Damage Types”. | C30: A wild jungle causes vines to whiplash in five “Line 4” Ranges, each using the Power Whip Attack. A loud Exploud causes Stalactites to fall from the ceiling in three 3x3 Zones with the Rock Slide Attack.
A31: Attack Blowback | B31: A delayed change in the environment has occurred based on something that happened during this Round. Resolving the effects of this blowback should use a Standard action or Swift Action if resourceful. | C31: A machine overloads from a missed thunderbolt causing anyone who ends their turn adjacent to it to become Paralyzed, trees catching on fire from a flamethrower leading to an area of effect of Fire Hazards or a draco meteor landing on a grassland causing a cloud of pollen to haze the field, leading to a -2 to Accuracy for a Round.
A32: Battlefield Alteration | B32: The Battlefield has been altered somehow. One Effect enters the field or alters the terrain that either affects all Combatants, harms the Player’s Party or benefits the Boss’s Party. This usually is either Terrain being changed, Blessings entering the field or the Weather changing. | C32: The Weather changes to Thunderstorm. A Nidoking’s rampage leads to a lot of earthen blocking terrain being created on the field on a labyrinth pattern. Psionic aura created by an Alakazam lead to a protective aura on its allies, leading to 2 Activations of the Reflect Attack.
A33: Environmental Conduit | B33: Something appears on the Battlefield that likely has a connection with the Boss and causes a passive effect while it remains undestroyed. This “Conduit” is treated as Blocking Terrain and has HP equal to 20 times the Party’s Trainer Level. Alternatively, three “Conduits” can appear but they only have HP equal to 5 Times their Trainer Level. When it is destroyed, the effects that derived from it cease. | C33: Three paintings in a Haunted House start to look alive and at the end of each turn unless destroyed, they roll a Luck Check and on a 5 or under, they Curse someone within 3m of them. A massive generator starts to stir, creating a psychic aura that makes all Psychic Attacks have the Sureshot Keyword unless destroyed and increases in power each round. The Boss creates a crystal that gives it Immunity to Dark Type Damage while active.
A34: Fleeting Catastrophe | B34: Something has occurred on the battlefield that doesn’t have any immediate impact but if not dealt with somehow, it will cause something to occur at the end of the next round or a timer of your discretion. The result from this Catastrophe not being resolved could be another Lair Action but with more drastic impact. Resolving this Catastrophe should use a Standard action or Swift Action if resourceful. | C34: A generator starts to fizz and spark looking like it’ll explode. If the Party doesn’t destroy it before it explodes or stops the explosion, it’ll cause a Burst 2 Electric Special Attack with Massive Damage. Alternatively they could use it to their advantage and slide an enemy into its range! A Forest Fire is beginning and will double in Fire Hazards every round its not extinguished.
A35: Reactive Battlefield | B35: Something has occurred in the scene that requires a quick reaction from a Combatant in order to stave off its negative effects. Designate a Combatant or a maximum of a 3x3 Zone to be affected by this Lair Action. They then must perform a Luck Roll with a Modifier of their Skill Rank in a Skill allowed by the GM and a DC of 12. If they fail this Luck Roll, they’re affected by the negative effect, usually gaining a Status Affliction or Conditions or temporary penalty. The Modifier can be doubled before rolling as a Swift Action, Priority (Advanced). If it makes sense to, the Combatant can add an appropriate Skill Rank as a modifier to this Luck Roll. | C35: A cloud of dark smoke looms towards a Player that Suppresses them on a failed roll, they can use Occult Edu as their Skill Modifier or Intuition to determine the weird nature of the smoke. The earth shifts under a 2x2 zone from an Earthquake and on a failed roll they are Tripped, they can use Acrobatics as their Skill Modifier to represent their nimbleness.
A36: Reinforcements | B36: A Path has opened on the battlefield in which Pokemon that are allied to the Boss can enter the field. A Minion (Or two if there are 3+ Players in the Party) enters the Field when this Lair Action is used and at the end of every subsequent Round this isn’t resolved. Resolving this Lair Action should use a Standard action or Swift Action if resourceful. | C36: A rift in space is opened and a Solrock comes out. The player’s Metagross attacks the portal with a Psychic and it fizzles out. Goomy start to wander out of a swamp lake. The player’s Pangoro stands nearby the lake and uses a Swift Action to intimidate and stave off any other goomy from joining the encounter.

Sheet Item Data
A1: Valuables | B1: Valuables Effect | C1: Consumables | D1: Consumables Effect | E1: Equipment | F1: Equipment Effect | G1: Weapon List | I1: Armor List | K1: Pokemon List | M1: All Items | N1: All Effects
A2: =IFERROR(__xludf.DUMMYFUNCTION("IMPORTRANGE('Homebrew Sheet'!$A$6,""'Items'!$A$2:$F$101"")"),"") | G2: =IFERROR(__xludf.DUMMYFUNCTION("QUERY($E$2:F1001,""select Col1,Col2 where Col2 contains 'Weapon]' or Col2 contains 'Any]'"",-1)"),"Braced Shield") -> Braced Shield | H2: =IFERROR(__xludf.DUMMYFUNCTION("""COMPUTED_VALUE"""),"While Equipped, whenever the user uses a Defend Maneuver, the Target has Damage Reduction equal to your Tier Value for the duration of the Maneuver. If the Target is no longer Adjacent to you, they do not benefit from this Effect [Medium] [Equipment - Wea"&"pon]") -> While Equipped, whenever the user uses a Defend Maneuver, the Target has Damage Reduction equal to your Tier Value for the duration of the Maneuver. If the Target is no longer Adjacent to you, they do not benefit from this Effect [Medium] [Equipment - Weapon] | I2: =IFERROR(__xludf.DUMMYFUNCTION("QUERY($E$2:F1001,""select Col1,Col2 where Col2 contains 'Armor]' or Col2 contains 'Any]'"",-1)"),"Arcane Armor ") -> Arcane Armor | J2: =IFERROR(__xludf.DUMMYFUNCTION("""COMPUTED_VALUE"""),"While Equipped, the user has +10 Damage Reduction and their Special Defense CS their Default CS Value set to +1. While Equipped, the user has their Default Movement Value lowered by -2. You must be Trainer Level 10+ to equip this. [Large] [Equipment - Ar"&"mor]") -> While Equipped, the user has +10 Damage Reduction and their Special Defense CS their Default CS Value set to +1. While Equipped, the user has their Default Movement Value lowered by -2. You must be Trainer Level 10+ to equip this. [Large] [Equipment - Armor] | K2: =IFERROR(__xludf.DUMMYFUNCTION("QUERY($E$2:F1001,""select Col1,Col2 where Col2 contains '[Pokemon]'"")"),"Air Balloon") -> Air Balloon | L2: =IFERROR(__xludf.DUMMYFUNCTION("""COMPUTED_VALUE"""),"This Item may only be equipped by Small Pokemon. While this Item is equipped, the User is immune to Attacks with the Groundsource Keyword and gains the Flier Capability. [Large] [Pokemon]") -> This Item may only be equipped by Small Pokemon. While this Item is equipped, the User is immune to Attacks with the Groundsource Keyword and gains the Flier Capability. [Large] [Pokemon] | M2: =IFERROR(__xludf.DUMMYFUNCTION("UNIQUE(QUERY({QUERY({$A$2:$B1001;$C$2:$D1001;$E$2:$F1001},""select Col1,Col2 where Col1 is not null"")},""select * order by Col1""))"),"(X) Shard") -> (X) Shard | N2: =IFERROR(__xludf.DUMMYFUNCTION("""COMPUTED_VALUE"""),"A Shard can be expended as a Free Action in the user's Inventory upon hitting a Damaging Attack that corresponds to an associated Type to increase its Damage Base by +3. The user may only expend one Shard per Attack. A Shard can come in any of the followi"&"ng colors and has the associated Types. Red (Fire, Fairy, Psychic), Orange (Normal, Fighting, Dragon), Yellow (Electric, Rock, Steel), Green (Bug, Grass, Ground), Blue (Flying, Ice, Water), Violet (Dark, Ghost, Poison). [Small] [Consumable] [Pokemon]") -> A Shard can be expended as a Free Action in the user's Inventory upon hitting a Damaging Attack that corresponds to an associated Type to increase its Damage Base by +3. The user may only expend one Shard per Attack. A Shard can come in any of the following colors and has the associated Types. Red (Fire, Fairy, Psychic), Orange (Normal, Fighting, Dragon), Yellow (Electric, Rock, Steel), Green (Bug, Grass, Ground), Blue (Flying, Ice, Water), Violet (Dark, Ghost, Poison). [Small] [Consumable] [Pokemon]
G3: =IFERROR(__xludf.DUMMYFUNCTION("""COMPUTED_VALUE"""),"Fine Weapon") -> Fine Weapon | H3: =IFERROR(__xludf.DUMMYFUNCTION("""COMPUTED_VALUE"""),"To determine the Effects of this Weapon while Equipped, refer to the ""Creating Weapon Item's Section in the Core Book. [Medium or Large] [Equipment - Weapon]") -> To determine the Effects of this Weapon while Equipped, refer to the "Creating Weapon Item's Section in the Core Book. [Medium or Large] [Equipment - Weapon] | I3: =IFERROR(__xludf.DUMMYFUNCTION("""COMPUTED_VALUE"""),"Assault Vest") -> Assault Vest | J3: =IFERROR(__xludf.DUMMYFUNCTION("""COMPUTED_VALUE"""),"While this Item is Equipped, the user gains a TIck of Temporary Hit Points whenever they're hit by a Physical Atack after Damage Calculations [Equipment - Armor] [[Large] [Pokemon]") -> While this Item is Equipped, the user gains a TIck of Temporary Hit Points whenever they're hit by a Physical Atack after Damage Calculations [Equipment - Armor] [[Large] [Pokemon] | K3: =IFERROR(__xludf.DUMMYFUNCTION("""COMPUTED_VALUE"""),"Analytic Lens") -> Analytic Lens | L3: =IFERROR(__xludf.DUMMYFUNCTION("""COMPUTED_VALUE"""),"While this Item is Equipped, the user has +1 to Effect Ranges. [Equipment] [Medium] [Pokemon]") -> While this Item is Equipped, the user has +1 to Effect Ranges. [Equipment] [Medium] [Pokemon] | M3: =IFERROR(__xludf.DUMMYFUNCTION("""COMPUTED_VALUE"""),"Ability Capsule") -> Ability Capsule | N3: =IFERROR(__xludf.DUMMYFUNCTION("""COMPUTED_VALUE"""),"When this Item is created, the GM will choose any Ability. When this Item is expended, choose a Pokemon you own. The Target may choose that Ability whenever they would be able to learn one, instead of one from their natural Ability List. [Small] [Consumab"&"le]") -> When this Item is created, the GM will choose any Ability. When this Item is expended, choose a Pokemon you own. The Target may choose that Ability whenever they would be able to learn one, instead of one from their natural Ability List. [Small] [Consumable]
G4: =IFERROR(__xludf.DUMMYFUNCTION("""COMPUTED_VALUE"""),"Heavy Shield") -> Heavy Shield | H4: =IFERROR(__xludf.DUMMYFUNCTION("""COMPUTED_VALUE"""),"While Equipped, whenever the user uses a Defend Maneuver, the Target has Damage Reduction equal to your Tier Value for the duration of the Maneuver. If the Target is no longer Adjacent to you, they do not benefit from this Effect. Additionally, while Equi"&"pped, you may use a Swift Action to gain Damage Reduction equal to your Tier Value for a Full Round. You must be Trainer Level 5+ to equip this. [Large] [Equipment - Weapon]") -> While Equipped, whenever the user uses a Defend Maneuver, the Target has Damage Reduction equal to your Tier Value for the duration of the Maneuver. If the Target is no longer Adjacent to you, they do not benefit from this Effect. Additionally, while Equipped, you may use a Swift Action to gain Damage Reduction equal to your Tier Value for a Full Round. You must be Trainer Level 5+ to equip this. [Large] [Equipment - Weapon] | I4: =IFERROR(__xludf.DUMMYFUNCTION("""COMPUTED_VALUE"""),"Covert Cloak") -> Covert Cloak | J4: =IFERROR(__xludf.DUMMYFUNCTION("""COMPUTED_VALUE"""),"While Equipped, Attacks against the user have a -2 Penalty to Effect Ranges. [Medium] [Equipment - Armor] [Pokemon]") -> While Equipped, Attacks against the user have a -2 Penalty to Effect Ranges. [Medium] [Equipment - Armor] [Pokemon] | K4: =IFERROR(__xludf.DUMMYFUNCTION("""COMPUTED_VALUE"""),"Assault Vest") -> Assault Vest | L4: =IFERROR(__xludf.DUMMYFUNCTION("""COMPUTED_VALUE"""),"While this Item is Equipped, the user gains a TIck of Temporary Hit Points whenever they're hit by a Physical Atack after Damage Calculations [Equipment - Armor] [[Large] [Pokemon]") -> While this Item is Equipped, the user gains a TIck of Temporary Hit Points whenever they're hit by a Physical Atack after Damage Calculations [Equipment - Armor] [[Large] [Pokemon] | M4: =IFERROR(__xludf.DUMMYFUNCTION("""COMPUTED_VALUE"""),"Air Balloon") -> Air Balloon | N4: =IFERROR(__xludf.DUMMYFUNCTION("""COMPUTED_VALUE"""),"This Item may only be equipped by Small Pokemon. While this Item is equipped, the User is immune to Attacks with the Groundsource Keyword and gains the Flier Capability. [Large] [Pokemon]") -> This Item may only be equipped by Small Pokemon. While this Item is equipped, the User is immune to Attacks with the Groundsource Keyword and gains the Flier Capability. [Large] [Pokemon]
G5: =IFERROR(__xludf.DUMMYFUNCTION("""COMPUTED_VALUE"""),"Legendary Weapon") -> Legendary Weapon | H5: =IFERROR(__xludf.DUMMYFUNCTION("""COMPUTED_VALUE"""),"To determine the Effects of this Weapon while Equipped, refer to the ""Creating Weapon Item's Section in the Core Book. [Medium or Large] [Equipment - Weapon]") -> To determine the Effects of this Weapon while Equipped, refer to the "Creating Weapon Item's Section in the Core Book. [Medium or Large] [Equipment - Weapon] | I5: =IFERROR(__xludf.DUMMYFUNCTION("""COMPUTED_VALUE"""),"Crude Armor") -> Crude Armor | J5: =IFERROR(__xludf.DUMMYFUNCTION("""COMPUTED_VALUE"""),"While Equipped, the user has +5 Damage Reduction. [Medium] [Equipment - Armor]") -> While Equipped, the user has +5 Damage Reduction. [Medium] [Equipment - Armor] | K5: =IFERROR(__xludf.DUMMYFUNCTION("""COMPUTED_VALUE"""),"Berserk Belt") -> Berserk Belt | L5: =IFERROR(__xludf.DUMMYFUNCTION("""COMPUTED_VALUE"""),"While this Item is Equipped, whenever the user causes an Enemy to faint via a Damaging Attack, they gain +1 CS to Attack or Special Attack. [Equipment] [Medium] [Pokemon]") -> While this Item is Equipped, whenever the user causes an Enemy to faint via a Damaging Attack, they gain +1 CS to Attack or Special Attack. [Equipment] [Medium] [Pokemon] | M5: =IFERROR(__xludf.DUMMYFUNCTION("""COMPUTED_VALUE"""),"Alarm Rune [Occult]") -> Alarm Rune [Occult] | N5: =IFERROR(__xludf.DUMMYFUNCTION("""COMPUTED_VALUE"""),"Cost: 4 Counters Effect: This Rune may be inscribed onto the surface of any object and be given an appropriate trigger condition, such as the inscribed book or door being opened. If the Trigger occurs, the rune lights up and you telepathically hear an ala"&"rm in your head to alert you. If you are further than a Mile from your Alarm Rune, it cannot be triggered. You can only have one Alarm Rune inscribed at a time.This can only be used by a Rune Master [Small] [Consumable] Advanced: The Rune can be triggered"&" and alert you regardless of your distance from it. You can have up to 3 Alarm Runes inscribed at a time.") -> Cost: 4 Counters Effect: This Rune may be inscribed onto the surface of any object and be given an appropriate trigger condition, such as the inscribed book or door being opened. If the Trigger occurs, the rune lights up and you telepathically hear an alarm in your head to alert you. If you are further than a Mile from your Alarm Rune, it cannot be triggered. You can only have one Alarm Rune inscribed at a time.This can only be used by a Rune Master [Small] [Consumable] Advanced: The Rune can be triggered and alert you regardless of your distance from it. You can have up to 3 Alarm Runes inscribed at a time.
G6: =IFERROR(__xludf.DUMMYFUNCTION("""COMPUTED_VALUE"""),"Ranger Styler") -> Ranger Styler | H6: =IFERROR(__xludf.DUMMYFUNCTION("""COMPUTED_VALUE"""),"Outside of Combat, whenever a Pokemon would be in a state where they could be Captured by a Pokeball, you may use this Item to cause them to become a Companion (See Mechanics). While Equipped, as a Standard Action you may Target an Enemy within 5m and per"&"form a Command or Charm Check opposed by their Focus. If they fail, choose one of the following Effects to apply: [Medium] [Equipment - Weapon] » Guard Break - The next Attack that Targets them ignores Evasion. » Pacify - During their next Turn, the Targe"&"t’s Damaging Attacks are resisted by an additional step. » Restrain - Until the end of their next Turn, the Target either becomes Trapped by an Ally or Yourself or has their Movement Value halved. The Ally must be within 3m of the Target to be Trapped. ") -> Outside of Combat, whenever a Pokemon would be in a state where they could be Captured by a Pokeball, you may use this Item to cause them to become a Companion (See Mechanics). While Equipped, as a Standard Action you may Target an Enemy within 5m and perform a Command or Charm Check opposed by their Focus. If they fail, choose one of the following Effects to apply: [Medium] [Equipment - Weapon] » Guard Break - The next Attack that Targets them ignores Evasion. » Pacify - During their next Turn, the Target’s Damaging Attacks are resisted by an additional step. » Restrain - Until the end of their next Turn, the Target either becomes Trapped by an Ally or Yourself or has their Movement Value halved. The Ally must be within 3m of the Target to be Trapped. | I6: =IFERROR(__xludf.DUMMYFUNCTION("""COMPUTED_VALUE"""),"Heavy Armor") -> Heavy Armor | J6: =IFERROR(__xludf.DUMMYFUNCTION("""COMPUTED_VALUE"""),"While Equipped, the user has +10 Damage Reduction and their Defense CS their Default CS Value set to +1. While Equipped, the user has their Default Movement Value lowered by -2. You must be Trainer Level 10+ to equip this. [Large] [Equipment - Armor]") -> While Equipped, the user has +10 Damage Reduction and their Defense CS their Default CS Value set to +1. While Equipped, the user has their Default Movement Value lowered by -2. You must be Trainer Level 10+ to equip this. [Large] [Equipment - Armor] | K6: =IFERROR(__xludf.DUMMYFUNCTION("""COMPUTED_VALUE"""),"Blessed Relic") -> Blessed Relic | L6: =IFERROR(__xludf.DUMMYFUNCTION("""COMPUTED_VALUE"""),"While this Item is Equipped, the user has +2 to Save Checks. [Equipment] [Medium] [Pokemon]") -> While this Item is Equipped, the user has +2 to Save Checks. [Equipment] [Medium] [Pokemon] | M6: =IFERROR(__xludf.DUMMYFUNCTION("""COMPUTED_VALUE"""),"Analytic Lens") -> Analytic Lens | N6: =IFERROR(__xludf.DUMMYFUNCTION("""COMPUTED_VALUE"""),"While this Item is Equipped, the user has +1 to Effect Ranges. [Equipment] [Medium] [Pokemon]") -> While this Item is Equipped, the user has +1 to Effect Ranges. [Equipment] [Medium] [Pokemon]
G7: =IFERROR(__xludf.DUMMYFUNCTION("""COMPUTED_VALUE"""),"Simple Weapon") -> Simple Weapon | H7: =IFERROR(__xludf.DUMMYFUNCTION("""COMPUTED_VALUE"""),"To determine the Effects of this Weapon while Equipped, refer to the ""Creating Weapon Item's Section in the Core Book. [Medium or Large] [Equipment - Weapon]") -> To determine the Effects of this Weapon while Equipped, refer to the "Creating Weapon Item's Section in the Core Book. [Medium or Large] [Equipment - Weapon] | I7: =IFERROR(__xludf.DUMMYFUNCTION("""COMPUTED_VALUE"""),"High Quality Heavy Armor") -> High Quality Heavy Armor | J7: =IFERROR(__xludf.DUMMYFUNCTION("""COMPUTED_VALUE"""),"While Equipped, the user has +20 Damage Reduction. You must be Trainer Level 15+ to equip this. [Large] [Equipment - Armor]") -> While Equipped, the user has +20 Damage Reduction. You must be Trainer Level 15+ to equip this. [Large] [Equipment - Armor] | K7: =IFERROR(__xludf.DUMMYFUNCTION("""COMPUTED_VALUE"""),"Cargo Bag") -> Cargo Bag | L7: =IFERROR(__xludf.DUMMYFUNCTION("""COMPUTED_VALUE"""),"While Equipped, the user has 4 Inventory Slots (Pokemon cannot use these Items). An adjacent Trainer may equip or use Items in these Slots as if they were in their own Inventory. Only Pokemon may equip this Item. Large Items cannot be put in these Slots i"&"f the user’s size is Small. [Large] [Pokemon] [Inventory 2]") -> While Equipped, the user has 4 Inventory Slots (Pokemon cannot use these Items). An adjacent Trainer may equip or use Items in these Slots as if they were in their own Inventory. Only Pokemon may equip this Item. Large Items cannot be put in these Slots if the user’s size is Small. [Large] [Pokemon] [Inventory 2] | M7: =IFERROR(__xludf.DUMMYFUNCTION("""COMPUTED_VALUE"""),"Arcane Armor ") -> Arcane Armor | N7: =IFERROR(__xludf.DUMMYFUNCTION("""COMPUTED_VALUE"""),"While Equipped, the user has +10 Damage Reduction and their Special Defense CS their Default CS Value set to +1. While Equipped, the user has their Default Movement Value lowered by -2. You must be Trainer Level 10+ to equip this. [Large] [Equipment - Ar"&"mor]") -> While Equipped, the user has +10 Damage Reduction and their Special Defense CS their Default CS Value set to +1. While Equipped, the user has their Default Movement Value lowered by -2. You must be Trainer Level 10+ to equip this. [Large] [Equipment - Armor]
G8: =IFERROR(__xludf.DUMMYFUNCTION("""COMPUTED_VALUE"""),"Training Weapon") -> Training Weapon | H8: =IFERROR(__xludf.DUMMYFUNCTION("""COMPUTED_VALUE"""),"To determine the Effects of this Weapon while Equipped, refer to the ""Creating Weapon Item's Section in the Core Book. [Medium or Large] [Equipment - Weapon]") -> To determine the Effects of this Weapon while Equipped, refer to the "Creating Weapon Item's Section in the Core Book. [Medium or Large] [Equipment - Weapon] | I8: =IFERROR(__xludf.DUMMYFUNCTION("""COMPUTED_VALUE"""),"High Quality Light Armor") -> High Quality Light Armor | J8: =IFERROR(__xludf.DUMMYFUNCTION("""COMPUTED_VALUE"""),"While Equipped, the user has +10 Damage Reduction. You must be Trainer Level 15+ to equip this. [Medium] [Equipment - Armor]") -> While Equipped, the user has +10 Damage Reduction. You must be Trainer Level 15+ to equip this. [Medium] [Equipment - Armor] | K8: =IFERROR(__xludf.DUMMYFUNCTION("""COMPUTED_VALUE"""),"Covert Cloak") -> Covert Cloak | L8: =IFERROR(__xludf.DUMMYFUNCTION("""COMPUTED_VALUE"""),"While Equipped, Attacks against the user have a -2 Penalty to Effect Ranges. [Medium] [Equipment - Armor] [Pokemon]") -> While Equipped, Attacks against the user have a -2 Penalty to Effect Ranges. [Medium] [Equipment - Armor] [Pokemon] | M8: =IFERROR(__xludf.DUMMYFUNCTION("""COMPUTED_VALUE"""),"Artificing Kit") -> Artificing Kit | N8: =IFERROR(__xludf.DUMMYFUNCTION("""COMPUTED_VALUE"""),"As a Downtime Action you may perform an Occult, Nature or Tech Edu Skill Check. If an area would be less likely to find shards, perform it with a Bane. if it would be more likely to find shards such as in a cave, perform it with a Boon. For each Success, "&"you find a Shard Item. Whenever you gain a shard this way, roll a d6 to determine the color. 1 is Red, 2 is Orange, 3 is Yellow, 4 is Green, 5 is Blue, 6 is Violet. [Medium] ") -> As a Downtime Action you may perform an Occult, Nature or Tech Edu Skill Check. If an area would be less likely to find shards, perform it with a Bane. if it would be more likely to find shards such as in a cave, perform it with a Boon. For each Success, you find a Shard Item. Whenever you gain a shard this way, roll a d6 to determine the color. 1 is Red, 2 is Orange, 3 is Yellow, 4 is Green, 5 is Blue, 6 is Violet. [Medium]
I9: =IFERROR(__xludf.DUMMYFUNCTION("""COMPUTED_VALUE"""),"Light Armor") -> Light Armor | J9: =IFERROR(__xludf.DUMMYFUNCTION("""COMPUTED_VALUE"""),"While Equipped, the user has +10 Damage Reduction. You must be Trainer Level 5+ to equip this. [Large] [Equipment - Armor]") -> While Equipped, the user has +10 Damage Reduction. You must be Trainer Level 5+ to equip this. [Large] [Equipment - Armor] | K9: =IFERROR(__xludf.DUMMYFUNCTION("""COMPUTED_VALUE"""),"Dodge Scarf") -> Dodge Scarf | L9: =IFERROR(__xludf.DUMMYFUNCTION("""COMPUTED_VALUE"""),"While this Item is Equipped, the user has a bonus to Evasion equal to their Tier Level. As a Reaction + Movement Action, they may treat this bonus as Uncapped until the start of their next Turn. [Equipment] [Large] [Pokemon]") -> While this Item is Equipped, the user has a bonus to Evasion equal to their Tier Level. As a Reaction + Movement Action, they may treat this bonus as Uncapped until the start of their next Turn. [Equipment] [Large] [Pokemon] | M9: =IFERROR(__xludf.DUMMYFUNCTION("""COMPUTED_VALUE"""),"Artisan Kit (X)") -> Artisan Kit (X) | N9: =IFERROR(__xludf.DUMMYFUNCTION("""COMPUTED_VALUE"""),"Whenever you Innovate or Research during a Downtime Phase and use an Exertion Modifier, if it’s for something that is related to (X), you reroll all dice that land on a 1. [Large]") -> Whenever you Innovate or Research during a Downtime Phase and use an Exertion Modifier, if it’s for something that is related to (X), you reroll all dice that land on a 1. [Large]
I10: =IFERROR(__xludf.DUMMYFUNCTION("""COMPUTED_VALUE"""),"Psionic Vest") -> Psionic Vest | J10: =IFERROR(__xludf.DUMMYFUNCTION("""COMPUTED_VALUE"""),"While this Item is Equipped, the user gains a TIck of Temporary Hit Points whenever they're hit by a Special Atack after Damage Calculations [Equipment - Armor] [[Large] [Pokemon]") -> While this Item is Equipped, the user gains a TIck of Temporary Hit Points whenever they're hit by a Special Atack after Damage Calculations [Equipment - Armor] [[Large] [Pokemon] | K10: =IFERROR(__xludf.DUMMYFUNCTION("""COMPUTED_VALUE"""),"Eject Module") -> Eject Module | L10: =IFERROR(__xludf.DUMMYFUNCTION("""COMPUTED_VALUE"""),"This Item may only be equipped by a Pokemon. While this Item is Equipped, whenever the User is hit with an Attack, after Damage Resolution they may choose to be recalled as a Reaction, Free Action. Their Trainer may then send out a new Pokemon as a Free A"&"ction in the same spot the holder was. This cannot be used if the User fainted as a result of the Triggering Attack. [Medium] [Equipment] [Pokemon]") -> This Item may only be equipped by a Pokemon. While this Item is Equipped, whenever the User is hit with an Attack, after Damage Resolution they may choose to be recalled as a Reaction, Free Action. Their Trainer may then send out a new Pokemon as a Free Action in the same spot the holder was. This cannot be used if the User fainted as a result of the Triggering Attack. [Medium] [Equipment] [Pokemon] | M10: =IFERROR(__xludf.DUMMYFUNCTION("""COMPUTED_VALUE"""),"Artisan Pack") -> Artisan Pack | N10: =IFERROR(__xludf.DUMMYFUNCTION("""COMPUTED_VALUE"""),"As an Extended Action, choose a [Small] Item. While Equipped, you treat that item as if it had the [Resource] Keyword within GM approval. If this Item is Impaired, you cannot access any Items within these Slots. [Medium] [Equipment]") -> As an Extended Action, choose a [Small] Item. While Equipped, you treat that item as if it had the [Resource] Keyword within GM approval. If this Item is Impaired, you cannot access any Items within these Slots. [Medium] [Equipment]
I11: =IFERROR(__xludf.DUMMYFUNCTION("""COMPUTED_VALUE"""),"Rocky Helmet") -> Rocky Helmet | J11: =IFERROR(__xludf.DUMMYFUNCTION("""COMPUTED_VALUE"""),"While this Item is Equipped, whenever the user is Targeted by a Melee Attack, the Attacker loses a Tick of Hit Points. [Equipment - Armor] [Large] [Pokemon]") -> While this Item is Equipped, whenever the user is Targeted by a Melee Attack, the Attacker loses a Tick of Hit Points. [Equipment - Armor] [Large] [Pokemon] | K11: =IFERROR(__xludf.DUMMYFUNCTION("""COMPUTED_VALUE"""),"Focus Sash") -> Focus Sash | L11: =IFERROR(__xludf.DUMMYFUNCTION("""COMPUTED_VALUE"""),"While this Item is Equipped, the user has the Endure Attack added to their Attack List without taking a Slot. If the Endure Attack is used, the User’s Positive Combat Stages are reset to their Default Value. [Large] [Equipment] [Pokemon]") -> While this Item is Equipped, the user has the Endure Attack added to their Attack List without taking a Slot. If the Endure Attack is used, the User’s Positive Combat Stages are reset to their Default Value. [Large] [Equipment] [Pokemon] | M11: =IFERROR(__xludf.DUMMYFUNCTION("""COMPUTED_VALUE"""),"Assault Vest") -> Assault Vest | N11: =IFERROR(__xludf.DUMMYFUNCTION("""COMPUTED_VALUE"""),"While this Item is Equipped, the user gains a TIck of Temporary Hit Points whenever they're hit by a Physical Atack after Damage Calculations [Equipment - Armor] [[Large] [Pokemon]") -> While this Item is Equipped, the user gains a TIck of Temporary Hit Points whenever they're hit by a Physical Atack after Damage Calculations [Equipment - Armor] [[Large] [Pokemon]
K12: =IFERROR(__xludf.DUMMYFUNCTION("""COMPUTED_VALUE"""),"Jewelry") -> Jewelry | L12: =IFERROR(__xludf.DUMMYFUNCTION("""COMPUTED_VALUE"""),"This Item does nothing without being given an effect by the GM. [Small] [Equipment] [Pokemon]") -> This Item does nothing without being given an effect by the GM. [Small] [Equipment] [Pokemon] | M12: =IFERROR(__xludf.DUMMYFUNCTION("""COMPUTED_VALUE"""),"Bardic Instrument") -> Bardic Instrument | N12: =IFERROR(__xludf.DUMMYFUNCTION("""COMPUTED_VALUE"""),"When this Item is created, choose two of the following Attacks to apply to it. While this Item is equipped, the user may use those Attacks. If this Item is Large, instead choose three. [Large or Medium] [Equipment] Options are: Heal Bell, Sing, Screech,So"&"nic Boom, Supersonic or Metal Sound") -> When this Item is created, choose two of the following Attacks to apply to it. While this Item is equipped, the user may use those Attacks. If this Item is Large, instead choose three. [Large or Medium] [Equipment] Options are: Heal Bell, Sing, Screech,Sonic Boom, Supersonic or Metal Sound
K13: =IFERROR(__xludf.DUMMYFUNCTION("""COMPUTED_VALUE"""),"Large Gadget") -> Large Gadget | L13: =IFERROR(__xludf.DUMMYFUNCTION("""COMPUTED_VALUE"""),"When this Item is created, the GM will determine what the effect of the Gadget is upon usage. While equipped, the user benefits from the effects of the Gadget. [Large] [Equipment] [Pokemon]") -> When this Item is created, the GM will determine what the effect of the Gadget is upon usage. While equipped, the user benefits from the effects of the Gadget. [Large] [Equipment] [Pokemon] | M13: =IFERROR(__xludf.DUMMYFUNCTION("""COMPUTED_VALUE"""),"Basic Healing Potion") -> Basic Healing Potion | N13: =IFERROR(__xludf.DUMMYFUNCTION("""COMPUTED_VALUE"""),"Choose one of the following Effects to apply to the Target. A Combatant cannot be Targeted by a ‘Healing Potion’ more than once per Scene. [Throwable] [Small] [Consumable] » They restore 3 Ticks of Hit Points or 50 HP, whichever is higher. » They are cu"&"red of 1 Status Affliction of your choice. » They are revived and set to 1 Tick of Hit Points or 20 Hit Points, whichever is higher.") -> Choose one of the following Effects to apply to the Target. A Combatant cannot be Targeted by a ‘Healing Potion’ more than once per Scene. [Throwable] [Small] [Consumable] » They restore 3 Ticks of Hit Points or 50 HP, whichever is higher. » They are cured of 1 Status Affliction of your choice. » They are revived and set to 1 Tick of Hit Points or 20 Hit Points, whichever is higher.
K14: =IFERROR(__xludf.DUMMYFUNCTION("""COMPUTED_VALUE"""),"Leftovers") -> Leftovers | L14: =IFERROR(__xludf.DUMMYFUNCTION("""COMPUTED_VALUE"""),"While this Item is Equipped, as a Swift+Movement Action, the user may gain a Tick of Temporary Hit Points or restore a Tick of Hit Points [Medium] [Equipment] [Pokemon]") -> While this Item is Equipped, as a Swift+Movement Action, the user may gain a Tick of Temporary Hit Points or restore a Tick of Hit Points [Medium] [Equipment] [Pokemon] | M14: =IFERROR(__xludf.DUMMYFUNCTION("""COMPUTED_VALUE"""),"Basic Healing Potion [Lethality]") -> Basic Healing Potion [Lethality] | N14: =IFERROR(__xludf.DUMMYFUNCTION("""COMPUTED_VALUE"""),"Choose one of the following Effects to apply to the Target. A Combatant cannot be Targeted by a ‘Healing Potion’ more than once per Scene. [Throwable] [Small] [Consumable] » They restore 3 Ticks of Hit Points or 50 HP, whichever is higher. » They are cure"&"d of 1 Status Affliction of your choice. » They are revived and set to 1 Tick of Hit Points or 20 Hit Points, whichever is higher. » They are cured of one Wound (Max 2 per Day - Extended Action only)") -> Choose one of the following Effects to apply to the Target. A Combatant cannot be Targeted by a ‘Healing Potion’ more than once per Scene. [Throwable] [Small] [Consumable] » They restore 3 Ticks of Hit Points or 50 HP, whichever is higher. » They are cured of 1 Status Affliction of your choice. » They are revived and set to 1 Tick of Hit Points or 20 Hit Points, whichever is higher. » They are cured of one Wound (Max 2 per Day - Extended Action only)
K15: =IFERROR(__xludf.DUMMYFUNCTION("""COMPUTED_VALUE"""),"Lucky Charm") -> Lucky Charm | L15: =IFERROR(__xludf.DUMMYFUNCTION("""COMPUTED_VALUE"""),"While this Item is Equipped, the user rerolls any Accuracy Roll that was a natural 1. [Equipment] [Medium] [Pokemon]") -> While this Item is Equipped, the user rerolls any Accuracy Roll that was a natural 1. [Equipment] [Medium] [Pokemon] | M15: =IFERROR(__xludf.DUMMYFUNCTION("""COMPUTED_VALUE"""),"Basic Malady Potion (Burned)") -> Basic Malady Potion (Burned) | N15: =IFERROR(__xludf.DUMMYFUNCTION("""COMPUTED_VALUE"""),"The Target hit by this Item becomes Burned. [Throwable] [Small] [Consumable]") -> The Target hit by this Item becomes Burned. [Throwable] [Small] [Consumable]
K16: =IFERROR(__xludf.DUMMYFUNCTION("""COMPUTED_VALUE"""),"Mega Stone") -> Mega Stone | L16: =IFERROR(__xludf.DUMMYFUNCTION("""COMPUTED_VALUE"""),"When this Item is created, choose a Pokemon and an Ability on their Dex List. While Equipped by a Pokemon, the user may shift into their Mega form as a Swift Action. When they do so, they gain +1 CS in a Stat of their choice, then gain the chosen Ability "&"until the end of the Scene. The user may not shift into their Mega Form during the Turn they used a Damaging Attack and they cannot use a Damaging Attatck for the rest of the Turn once they do shift into their Mega Form. [Medium] [Pokemon]") -> When this Item is created, choose a Pokemon and an Ability on their Dex List. While Equipped by a Pokemon, the user may shift into their Mega form as a Swift Action. When they do so, they gain +1 CS in a Stat of their choice, then gain the chosen Ability until the end of the Scene. The user may not shift into their Mega Form during the Turn they used a Damaging Attack and they cannot use a Damaging Attatck for the rest of the Turn once they do shift into their Mega Form. [Medium] [Pokemon] | M16: =IFERROR(__xludf.DUMMYFUNCTION("""COMPUTED_VALUE"""),"Basic Malady Potion (Enraged)") -> Basic Malady Potion (Enraged) | N16: =IFERROR(__xludf.DUMMYFUNCTION("""COMPUTED_VALUE"""),"The Target hit by this Item becomes Enraged. [Throwable] [Small] [Consumable]") -> The Target hit by this Item becomes Enraged. [Throwable] [Small] [Consumable]
